[2025-10-22T08:19:12.770+0000] {local_task_job_runner.py:120} INFO - ::group::Pre task execution logs
[2025-10-22T08:19:12.791+0000] {taskinstance.py:2076} INFO - Dependencies all met for dep_context=non-requeueable deps ti=<TaskInstance: minio_to_snowflake.load_snowflake scheduled__2025-10-22T02:35:00+00:00 [queued]>
[2025-10-22T08:19:12.796+0000] {taskinstance.py:2076} INFO - Dependencies all met for dep_context=requeueable deps ti=<TaskInstance: minio_to_snowflake.load_snowflake scheduled__2025-10-22T02:35:00+00:00 [queued]>
[2025-10-22T08:19:12.796+0000] {taskinstance.py:2306} INFO - Starting attempt 2 of 2
[2025-10-22T08:19:12.805+0000] {taskinstance.py:2330} INFO - Executing <Task(PythonOperator): load_snowflake> on 2025-10-22 02:35:00+00:00
[2025-10-22T08:19:12.812+0000] {logging_mixin.py:188} WARNING - /home/***/.local/lib/python3.12/site-packages/***/task/task_runner/standard_task_runner.py:62 DeprecationWarning: This process (pid=14546) is multi-threaded, use of fork() may lead to deadlocks in the child.
[2025-10-22T08:19:12.810+0000] {standard_task_runner.py:90} INFO - Running: ['***', 'tasks', 'run', 'minio_to_snowflake', 'load_snowflake', 'scheduled__2025-10-22T02:35:00+00:00', '--job-id', '160', '--raw', '--subdir', 'DAGS_FOLDER/minio_to_snowflake.py', '--cfg-path', '/tmp/tmpmv2c8xtw']
[2025-10-22T08:19:12.812+0000] {standard_task_runner.py:91} INFO - Job 160: Subtask load_snowflake
[2025-10-22T08:19:12.812+0000] {standard_task_runner.py:64} INFO - Started process 14556 to run task
[2025-10-22T08:19:12.848+0000] {task_command.py:426} INFO - Running <TaskInstance: minio_to_snowflake.load_snowflake scheduled__2025-10-22T02:35:00+00:00 [running]> on host 247b7821f06b
[2025-10-22T08:19:12.910+0000] {taskinstance.py:2648} INFO - Exporting env vars: AIRFLOW_CTX_DAG_EMAIL='jupudimanoj74@gmail.com' AIRFLOW_CTX_DAG_OWNER='***' AIRFLOW_CTX_DAG_ID='minio_to_snowflake' AIRFLOW_CTX_TASK_ID='load_snowflake' AIRFLOW_CTX_EXECUTION_DATE='2025-10-22T02:35:00+00:00' AIRFLOW_CTX_TRY_NUMBER='2' AIRFLOW_CTX_DAG_RUN_ID='scheduled__2025-10-22T02:35:00+00:00'
[2025-10-22T08:19:12.910+0000] {taskinstance.py:430} INFO - ::endgroup::
[2025-10-22T08:19:12.929+0000] {connection.py:408} INFO - Snowflake Connector for Python Version: 3.11.0, Python Version: 3.12.4, Platform: Linux-6.10.14-linuxkit-aarch64-with-glibc2.36
[2025-10-22T08:19:12.930+0000] {connection.py:1258} INFO - This connection is in OCSP Fail Open Mode. TLS Certificates would be checked for validity and revocation status. Any other Certificate Revocation related exceptions or OCSP Responder failures would be disregarded in favor of connectivity.
[2025-10-22T08:19:14.500+0000] {logging_mixin.py:188} INFO - Uploaded /tmp/minio_downloads/1760974267.json to Snowflake stage
[2025-10-22T08:19:14.704+0000] {logging_mixin.py:188} INFO - Uploaded /tmp/minio_downloads/1760974274.json to Snowflake stage
[2025-10-22T08:19:14.924+0000] {logging_mixin.py:188} INFO - Uploaded /tmp/minio_downloads/1760974282.json to Snowflake stage
[2025-10-22T08:19:15.071+0000] {logging_mixin.py:188} INFO - Uploaded /tmp/minio_downloads/1760974289.json to Snowflake stage
[2025-10-22T08:19:15.271+0000] {logging_mixin.py:188} INFO - Uploaded /tmp/minio_downloads/1760974296.json to Snowflake stage
[2025-10-22T08:19:15.474+0000] {logging_mixin.py:188} INFO - Uploaded /tmp/minio_downloads/1760974303.json to Snowflake stage
[2025-10-22T08:19:15.608+0000] {logging_mixin.py:188} INFO - Uploaded /tmp/minio_downloads/1760974311.json to Snowflake stage
[2025-10-22T08:19:15.750+0000] {logging_mixin.py:188} INFO - Uploaded /tmp/minio_downloads/1760974318.json to Snowflake stage
[2025-10-22T08:19:15.892+0000] {logging_mixin.py:188} INFO - Uploaded /tmp/minio_downloads/1760974325.json to Snowflake stage
[2025-10-22T08:19:16.040+0000] {logging_mixin.py:188} INFO - Uploaded /tmp/minio_downloads/1760976264.json to Snowflake stage
[2025-10-22T08:19:16.177+0000] {logging_mixin.py:188} INFO - Uploaded /tmp/minio_downloads/1760976271.json to Snowflake stage
[2025-10-22T08:19:16.310+0000] {logging_mixin.py:188} INFO - Uploaded /tmp/minio_downloads/1760976279.json to Snowflake stage
[2025-10-22T08:19:16.455+0000] {logging_mixin.py:188} INFO - Uploaded /tmp/minio_downloads/1760976286.json to Snowflake stage
[2025-10-22T08:19:16.609+0000] {logging_mixin.py:188} INFO - Uploaded /tmp/minio_downloads/1760976293.json to Snowflake stage
[2025-10-22T08:19:16.757+0000] {logging_mixin.py:188} INFO - Uploaded /tmp/minio_downloads/1760976300.json to Snowflake stage
[2025-10-22T08:19:16.896+0000] {logging_mixin.py:188} INFO - Uploaded /tmp/minio_downloads/1760976308.json to Snowflake stage
[2025-10-22T08:19:17.043+0000] {logging_mixin.py:188} INFO - Uploaded /tmp/minio_downloads/1760976315.json to Snowflake stage
[2025-10-22T08:19:17.175+0000] {logging_mixin.py:188} INFO - Uploaded /tmp/minio_downloads/1760976322.json to Snowflake stage
[2025-10-22T08:19:17.308+0000] {logging_mixin.py:188} INFO - Uploaded /tmp/minio_downloads/1760976329.json to Snowflake stage
[2025-10-22T08:19:17.460+0000] {logging_mixin.py:188} INFO - Uploaded /tmp/minio_downloads/1760976336.json to Snowflake stage
[2025-10-22T08:19:17.590+0000] {logging_mixin.py:188} INFO - Uploaded /tmp/minio_downloads/1760976343.json to Snowflake stage
[2025-10-22T08:19:17.728+0000] {logging_mixin.py:188} INFO - Uploaded /tmp/minio_downloads/1760976351.json to Snowflake stage
[2025-10-22T08:19:17.860+0000] {logging_mixin.py:188} INFO - Uploaded /tmp/minio_downloads/1760976358.json to Snowflake stage
[2025-10-22T08:19:17.990+0000] {logging_mixin.py:188} INFO - Uploaded /tmp/minio_downloads/1760976365.json to Snowflake stage
[2025-10-22T08:19:18.129+0000] {logging_mixin.py:188} INFO - Uploaded /tmp/minio_downloads/1760976372.json to Snowflake stage
[2025-10-22T08:19:18.279+0000] {logging_mixin.py:188} INFO - Uploaded /tmp/minio_downloads/1760976379.json to Snowflake stage
[2025-10-22T08:19:18.423+0000] {logging_mixin.py:188} INFO - Uploaded /tmp/minio_downloads/1760976386.json to Snowflake stage
[2025-10-22T08:19:18.570+0000] {logging_mixin.py:188} INFO - Uploaded /tmp/minio_downloads/1760976393.json to Snowflake stage
[2025-10-22T08:19:18.692+0000] {logging_mixin.py:188} INFO - Uploaded /tmp/minio_downloads/1760976401.json to Snowflake stage
[2025-10-22T08:35:33.191+0000] {taskinstance.py:441} INFO - ::group::Post task execution logs
[2025-10-22T08:35:33.192+0000] {taskinstance.py:2905} ERROR - Task failed with exception
Traceback (most recent call last):
  File "/home/airflow/.local/lib/python3.12/site-packages/airflow/models/taskinstance.py", line 465, in _execute_task
    result = _execute_callable(context=context, **execute_callable_kwargs)
             ^^^^^^^^^^^^^^^^^^^^^^^^^^^^^^^^^^^^^^^^^^^^^^^^^^^^^^^^^^^^^
  File "/home/airflow/.local/lib/python3.12/site-packages/airflow/models/taskinstance.py", line 432, in _execute_callable
    return execute_callable(context=context, **execute_callable_kwargs)
           ^^^^^^^^^^^^^^^^^^^^^^^^^^^^^^^^^^^^^^^^^^^^^^^^^^^^^^^^^^^^
  File "/home/airflow/.local/lib/python3.12/site-packages/airflow/models/baseoperator.py", line 401, in wrapper
    return func(self, *args, **kwargs)
           ^^^^^^^^^^^^^^^^^^^^^^^^^^^
  File "/home/airflow/.local/lib/python3.12/site-packages/airflow/operators/python.py", line 235, in execute
    return_value = self.execute_callable()
                   ^^^^^^^^^^^^^^^^^^^^^^^
  File "/home/airflow/.local/lib/python3.12/site-packages/airflow/operators/python.py", line 252, in execute_callable
    return self.python_callable(*self.op_args, **self.op_kwargs)
           ^^^^^^^^^^^^^^^^^^^^^^^^^^^^^^^^^^^^^^^^^^^^^^^^^^^^^
  File "/opt/airflow/dags/minio_to_snowflake.py", line 56, in load_to_snowflake
    cur.execute(f"PUT file://{f} @%bronze_stock_quotes_raw")
  File "/home/airflow/.local/lib/python3.12/site-packages/snowflake/connector/cursor.py", line 1080, in execute
    Error.errorhandler_wrapper(self.connection, self, error_class, errvalue)
  File "/home/airflow/.local/lib/python3.12/site-packages/snowflake/connector/errors.py", line 290, in errorhandler_wrapper
    handed_over = Error.hand_to_other_handler(
                  ^^^^^^^^^^^^^^^^^^^^^^^^^^^^
  File "/home/airflow/.local/lib/python3.12/site-packages/snowflake/connector/errors.py", line 345, in hand_to_other_handler
    cursor.errorhandler(connection, cursor, error_class, error_value)
  File "/home/airflow/.local/lib/python3.12/site-packages/snowflake/connector/errors.py", line 221, in default_errorhandler
    raise error_class(
snowflake.connector.errors.ProgrammingError: 000612 (02000): None: Result not found
[2025-10-22T08:35:33.205+0000] {taskinstance.py:1206} INFO - Marking task as FAILED. dag_id=minio_to_snowflake, task_id=load_snowflake, run_id=scheduled__2025-10-22T02:35:00+00:00, execution_date=20251022T023500, start_date=20251022T081912, end_date=20251022T083533
[2025-10-22T08:35:33.222+0000] {logging_mixin.py:188} WARNING - /home/***/.local/lib/python3.12/site-packages/***/utils/email.py:154 RemovedInAirflow3Warning: Fetching SMTP credentials from configuration variables will be deprecated in a future release. Please set credentials using a connection instead.
[2025-10-22T08:35:33.222+0000] {configuration.py:1053} WARNING - section/key [smtp/smtp_user] not found in config
[2025-10-22T08:35:33.222+0000] {email.py:271} INFO - Email alerting: attempt 1
[2025-10-22T08:35:33.230+0000] {configuration.py:1053} WARNING - section/key [smtp/smtp_user] not found in config
[2025-10-22T08:35:33.231+0000] {email.py:271} INFO - Email alerting: attempt 1
[2025-10-22T08:35:33.231+0000] {taskinstance.py:879} ERROR - Failed to send email to: ['jupudimanoj74@gmail.com']
Traceback (most recent call last):
  File "/home/airflow/.local/lib/python3.12/site-packages/airflow/models/taskinstance.py", line 2479, in _run_raw_task
    self._execute_task_with_callbacks(context, test_mode, session=session)
  File "/home/airflow/.local/lib/python3.12/site-packages/airflow/models/taskinstance.py", line 2676, in _execute_task_with_callbacks
    result = self._execute_task(context, task_orig)
             ^^^^^^^^^^^^^^^^^^^^^^^^^^^^^^^^^^^^^^
  File "/home/airflow/.local/lib/python3.12/site-packages/airflow/models/taskinstance.py", line 2701, in _execute_task
    return _execute_task(self, context, task_orig)
           ^^^^^^^^^^^^^^^^^^^^^^^^^^^^^^^^^^^^^^^
  File "/home/airflow/.local/lib/python3.12/site-packages/airflow/models/taskinstance.py", line 465, in _execute_task
    result = _execute_callable(context=context, **execute_callable_kwargs)
             ^^^^^^^^^^^^^^^^^^^^^^^^^^^^^^^^^^^^^^^^^^^^^^^^^^^^^^^^^^^^^
  File "/home/airflow/.local/lib/python3.12/site-packages/airflow/models/taskinstance.py", line 432, in _execute_callable
    return execute_callable(context=context, **execute_callable_kwargs)
           ^^^^^^^^^^^^^^^^^^^^^^^^^^^^^^^^^^^^^^^^^^^^^^^^^^^^^^^^^^^^
  File "/home/airflow/.local/lib/python3.12/site-packages/airflow/models/baseoperator.py", line 401, in wrapper
    return func(self, *args, **kwargs)
           ^^^^^^^^^^^^^^^^^^^^^^^^^^^
  File "/home/airflow/.local/lib/python3.12/site-packages/airflow/operators/python.py", line 235, in execute
    return_value = self.execute_callable()
                   ^^^^^^^^^^^^^^^^^^^^^^^
  File "/home/airflow/.local/lib/python3.12/site-packages/airflow/operators/python.py", line 252, in execute_callable
    return self.python_callable(*self.op_args, **self.op_kwargs)
           ^^^^^^^^^^^^^^^^^^^^^^^^^^^^^^^^^^^^^^^^^^^^^^^^^^^^^
  File "/opt/airflow/dags/minio_to_snowflake.py", line 56, in load_to_snowflake
    cur.execute(f"PUT file://{f} @%bronze_stock_quotes_raw")
  File "/home/airflow/.local/lib/python3.12/site-packages/snowflake/connector/cursor.py", line 1080, in execute
    Error.errorhandler_wrapper(self.connection, self, error_class, errvalue)
  File "/home/airflow/.local/lib/python3.12/site-packages/snowflake/connector/errors.py", line 290, in errorhandler_wrapper
    handed_over = Error.hand_to_other_handler(
                  ^^^^^^^^^^^^^^^^^^^^^^^^^^^^
  File "/home/airflow/.local/lib/python3.12/site-packages/snowflake/connector/errors.py", line 345, in hand_to_other_handler
    cursor.errorhandler(connection, cursor, error_class, error_value)
  File "/home/airflow/.local/lib/python3.12/site-packages/snowflake/connector/errors.py", line 221, in default_errorhandler
    raise error_class(
snowflake.connector.errors.ProgrammingError: 000612 (02000): None: Result not found

During handling of the above exception, another exception occurred:

Traceback (most recent call last):
  File "/home/airflow/.local/lib/python3.12/site-packages/airflow/models/taskinstance.py", line 1063, in _email_alert
    send_email(task.email, subject, html_content)
  File "/home/airflow/.local/lib/python3.12/site-packages/airflow/utils/email.py", line 80, in send_email
    return backend(
           ^^^^^^^^
  File "/home/airflow/.local/lib/python3.12/site-packages/airflow/utils/email.py", line 154, in send_email_smtp
    send_mime_email(e_from=mail_from, e_to=recipients, mime_msg=msg, conn_id=conn_id, dryrun=dryrun)
  File "/home/airflow/.local/lib/python3.12/site-packages/airflow/utils/email.py", line 273, in send_mime_email
    smtp_conn = _get_smtp_connection(smtp_host, smtp_port, smtp_timeout, smtp_ssl)
                ^^^^^^^^^^^^^^^^^^^^^^^^^^^^^^^^^^^^^^^^^^^^^^^^^^^^^^^^^^^^^^^^^^
  File "/home/airflow/.local/lib/python3.12/site-packages/airflow/utils/email.py", line 317, in _get_smtp_connection
    return smtplib.SMTP(host=host, port=port, timeout=timeout)
           ^^^^^^^^^^^^^^^^^^^^^^^^^^^^^^^^^^^^^^^^^^^^^^^^^^^
  File "/usr/local/lib/python3.12/smtplib.py", line 255, in __init__
    (code, msg) = self.connect(host, port)
                  ^^^^^^^^^^^^^^^^^^^^^^^^
  File "/usr/local/lib/python3.12/smtplib.py", line 341, in connect
    self.sock = self._get_socket(host, port, self.timeout)
                ^^^^^^^^^^^^^^^^^^^^^^^^^^^^^^^^^^^^^^^^^^
  File "/usr/local/lib/python3.12/smtplib.py", line 312, in _get_socket
    return socket.create_connection((host, port), timeout,
           ^^^^^^^^^^^^^^^^^^^^^^^^^^^^^^^^^^^^^^^^^^^^^^^
  File "/usr/local/lib/python3.12/socket.py", line 853, in create_connection
    raise exceptions[0]
  File "/usr/local/lib/python3.12/socket.py", line 838, in create_connection
    sock.connect(sa)
ConnectionRefusedError: [Errno 111] Connection refused

During handling of the above exception, another exception occurred:

Traceback (most recent call last):
  File "/home/airflow/.local/lib/python3.12/site-packages/airflow/models/taskinstance.py", line 877, in _handle_failure
    task_instance.email_alert(error, failure_context["task"])
  File "/home/airflow/.local/lib/python3.12/site-packages/airflow/models/taskinstance.py", line 3163, in email_alert
    _email_alert(task_instance=self, exception=exception, task=task)
  File "/home/airflow/.local/lib/python3.12/site-packages/airflow/models/taskinstance.py", line 1065, in _email_alert
    send_email(task.email, subject, html_content_err)
  File "/home/airflow/.local/lib/python3.12/site-packages/airflow/utils/email.py", line 80, in send_email
    return backend(
           ^^^^^^^^
  File "/home/airflow/.local/lib/python3.12/site-packages/airflow/utils/email.py", line 154, in send_email_smtp
    send_mime_email(e_from=mail_from, e_to=recipients, mime_msg=msg, conn_id=conn_id, dryrun=dryrun)
  File "/home/airflow/.local/lib/python3.12/site-packages/airflow/utils/email.py", line 273, in send_mime_email
    smtp_conn = _get_smtp_connection(smtp_host, smtp_port, smtp_timeout, smtp_ssl)
                ^^^^^^^^^^^^^^^^^^^^^^^^^^^^^^^^^^^^^^^^^^^^^^^^^^^^^^^^^^^^^^^^^^
  File "/home/airflow/.local/lib/python3.12/site-packages/airflow/utils/email.py", line 317, in _get_smtp_connection
    return smtplib.SMTP(host=host, port=port, timeout=timeout)
           ^^^^^^^^^^^^^^^^^^^^^^^^^^^^^^^^^^^^^^^^^^^^^^^^^^^
  File "/usr/local/lib/python3.12/smtplib.py", line 255, in __init__
    (code, msg) = self.connect(host, port)
                  ^^^^^^^^^^^^^^^^^^^^^^^^
  File "/usr/local/lib/python3.12/smtplib.py", line 341, in connect
    self.sock = self._get_socket(host, port, self.timeout)
                ^^^^^^^^^^^^^^^^^^^^^^^^^^^^^^^^^^^^^^^^^^
  File "/usr/local/lib/python3.12/smtplib.py", line 312, in _get_socket
    return socket.create_connection((host, port), timeout,
           ^^^^^^^^^^^^^^^^^^^^^^^^^^^^^^^^^^^^^^^^^^^^^^^
  File "/usr/local/lib/python3.12/socket.py", line 853, in create_connection
    raise exceptions[0]
  File "/usr/local/lib/python3.12/socket.py", line 838, in create_connection
    sock.connect(sa)
ConnectionRefusedError: [Errno 111] Connection refused
[2025-10-22T08:35:33.243+0000] {standard_task_runner.py:110} ERROR - Failed to execute job 160 for task load_snowflake (000612 (02000): None: Result not found; 14556)
[2025-10-22T08:35:33.266+0000] {local_task_job_runner.py:243} INFO - Task exited with return code 1
[2025-10-22T08:35:33.281+0000] {taskinstance.py:3503} INFO - 0 downstream tasks scheduled from follow-on schedule check
[2025-10-22T08:35:33.283+0000] {local_task_job_runner.py:222} INFO - ::endgroup::
